>>> 'Pkg.add("JFVM")' log
INFO: Cloning cache of JFVM from git://github.com/simulkade/JFVM.jl.git
INFO: Installing Color v0.4.5
INFO: Installing FixedPointNumbers v0.0.7
INFO: Installing Graphics v0.1.0
INFO: Installing JFVM v0.0.1
INFO: Installing LaTeXStrings v0.1.3
INFO: Installing PyCall v0.8.1
INFO: Installing PyPlot v1.5.3
INFO: Package database updated
INFO: METADATA is out-of-date â€” you may not have the latest version of JFVM
INFO: Use `Pkg.update()` to get the latest versions of your packages

>>> 'Pkg.test("JFVM")' log
Julia Version 0.4.0-dev+5779
Commit 6e80111* (2015-07-04 02:06 UTC)
Platform Info:
  System: Linux (x86_64-unknown-linux-gnu)
  CPU: Intel(R) Xeon(R) CPU E5-2650 0 @ 2.00GHz
  WORD_SIZE: 64
  BLAS: libopenblas (USE64BITINT DYNAMIC_ARCH NO_AFFINITY Nehalem)
  LAPACK: libopenblas
  LIBM: libopenlibm
  LLVM: libLLVM-3.3
INFO: Testing JFVM
Warning: New definition 
    call(Type{PyCall.PyDict}, Base.Associative{#K<:Any, Any}) at /home/vagrant/.julia/v0.4/PyCall/src/conversions.jl:464
is ambiguous with: 
    call(Type{PyCall.PyDict}, Base.Associative{Any, #V<:Any}) at /home/vagrant/.julia/v0.4/PyCall/src/conversions.jl:463.
To fix, define 
    call(Type{PyCall.PyDict}, Base.Associative{Any, Any})
before the new definition.
ERROR: LoadError: LoadError: LoadError: LoadError: TypeError: apply_type: in first parameter of NTuple, expected Int64, got Type{Type{T}}
 in include at ./boot.jl:254
 in include_from_node1 at ./loading.jl:133
 in reload_path at ./loading.jl:157
 in _require at ./loading.jl:69
 in require at ./loading.jl:55
 in include at ./boot.jl:254
 in include_from_node1 at ./loading.jl:133
 in reload_path at ./loading.jl:157
 in _require at ./loading.jl:69
 in require at ./loading.jl:55
 in include at ./boot.jl:254
 in include_from_node1 at ./loading.jl:133
 in reload_path at ./loading.jl:157
 in _require at ./loading.jl:69
 in require at ./loading.jl:52
 in include at ./boot.jl:254
 in include_from_node1 at loading.jl:133
 in process_options at ./client.jl:306
 in _start at ./client.jl:406
while loading /home/vagrant/.julia/v0.4/PyCall/src/PyCall.jl, in expression starting on line 381
while loading /home/vagrant/.julia/v0.4/PyPlot/src/PyPlot.jl, in expression starting on line 3
while loading /home/vagrant/.julia/v0.4/JFVM/src/JFVM.jl, in expression starting on line 3
while loading /home/vagrant/.julia/v0.4/JFVM/test/runtests.jl, in expression starting on line 1
================================[ ERROR: JFVM ]=================================

failed process: Process(`/home/vagrant/julia/bin/julia --check-bounds=yes --code-coverage=none --color=no /home/vagrant/.julia/v0.4/JFVM/test/runtests.jl`, ProcessExited(1)) [1]

================================================================================
INFO: No packages to install, update or remove
ERROR: JFVM had test errors
 in error at ./error.jl:21
 in test at pkg/entry.jl:746
 in anonymous at pkg/dir.jl:31
 in cd at file.jl:22
 in cd at pkg/dir.jl:31
 in test at pkg.jl:71
 in process_options at ./client.jl:282
 in _start at ./client.jl:406

>>> End of log
