>>> 'Pkg.add("JFVM")' log
INFO: Cloning cache of JFVM from git://github.com/simulkade/JFVM.jl.git
INFO: Installing ColorTypes v0.2.0
INFO: Installing Colors v0.6.0
INFO: Installing Conda v0.1.8
INFO: Installing Dates v0.4.4
INFO: Installing FixedPointNumbers v0.1.1
INFO: Installing JFVM v0.0.1
INFO: Installing LaTeXStrings v0.1.6
INFO: Installing PyCall v1.2.0
INFO: Installing PyPlot v2.1.1
INFO: Building PyCall
INFO: PyCall is using /usr/bin/python (Python 2.7.6) at /usr/bin/python, libpython = libpython2.7
INFO: Package database updated

>>> 'Pkg.test("JFVM")' log
Julia Version 0.4.1
Commit cbe1bee* (2015-11-08 10:33 UTC)
Platform Info:
  System: Linux (x86_64-unknown-linux-gnu)
  CPU: Intel(R) Xeon(R) CPU E3-1241 v3 @ 3.50GHz
  WORD_SIZE: 64
  BLAS: libopenblas (USE64BITINT DYNAMIC_ARCH NO_AFFINITY Nehalem)
  LAPACK: libopenblas64_
  LIBM: libopenlibm
  LLVM: libLLVM-3.3
INFO: Testing JFVM
INFO: Recompiling stale cache file /home/vagrant/.julia/lib/v0.4/PyPlot.ji for module PyPlot.
INFO: Recompiling stale cache file /home/vagrant/.julia/lib/v0.4/PyCall.ji for module PyCall.
ERROR: LoadError: LoadError: InitError: Failed to pyimport("matplotlib"): PyPlot will not work until you have a functioning matplotlib module.

For automated Matplotlib installation, try configuring PyCall to use the Conda Python distribution within Julia.  Relaunch Julia and run:
      ENV["PYTHON"]=""
      Pkg.build("PyCall")
      using PyPlot

pyimport exception was: PyError (:PyImport_ImportModule) <type 'exceptions.ImportError'>
ImportError('No module named matplotlib',)

 in __init__ at /home/vagrant/.julia/v0.4/PyPlot/src/PyPlot.jl:229
 in _require_from_serialized at loading.jl:84
 in _require_from_serialized at ./loading.jl:109
 in require at ./loading.jl:219
 in include at ./boot.jl:261
 in include_from_node1 at ./loading.jl:304
 in require at ./loading.jl:243
 in include at ./boot.jl:261
 in include_from_node1 at ./loading.jl:304
 in process_options at ./client.jl:280
 in _start at ./client.jl:378
during initialization of module PyPlot
while loading /home/vagrant/.julia/v0.4/JFVM/src/JFVM.jl, in expression starting on line 3
while loading /home/vagrant/.julia/v0.4/JFVM/test/runtests.jl, in expression starting on line 1
================================[ ERROR: JFVM ]=================================

failed process: Process(`/home/vagrant/julia/bin/julia --check-bounds=yes --code-coverage=none --color=no /home/vagrant/.julia/v0.4/JFVM/test/runtests.jl`, ProcessExited(1)) [1]

================================================================================
ERROR: JFVM had test errors
 in error at ./error.jl:21
 in test at pkg/entry.jl:803
 in anonymous at pkg/dir.jl:31
 in cd at file.jl:22
 in cd at pkg/dir.jl:31
 in test at pkg.jl:71
 in process_options at ./client.jl:257
 in _start at ./client.jl:378

>>> End of log
