>>> 'Pkg.add("ShapeModels")' log
INFO: Cloning cache of ShapeModels from git://github.com/rened/ShapeModels.jl.git
INFO: Installing ArrayViews v0.6.4
INFO: Installing Blosc v0.1.4
INFO: Installing FactCheck v0.4.1
INFO: Installing FunctionalData v0.1.0
INFO: Installing FunctionalDataUtils v0.1.0
INFO: Installing HDF5 v0.5.6
INFO: Installing MultivariateStats v0.2.1
INFO: Installing ShapeModels v0.0.3
INFO: Installing StatsBase v0.7.4
INFO: Installing StatsFuns v0.2.0
INFO: Building Blosc
INFO: Building HDF5
INFO: Building PyCall
INFO: PyCall is using /usr/bin/python (Python 2.7.6) at /usr/bin/python, libpython = libpython2.7
INFO: Package database updated
INFO: METADATA is out-of-date â€” you may not have the latest version of ShapeModels
INFO: Use `Pkg.update()` to get the latest versions of your packages

>>> 'Pkg.test("ShapeModels")' log
Julia Version 0.4.1
Commit cbe1bee* (2015-11-08 10:33 UTC)
Platform Info:
  System: Linux (x86_64-unknown-linux-gnu)
  CPU: Intel(R) Xeon(R) CPU E3-1241 v3 @ 3.50GHz
  WORD_SIZE: 64
  BLAS: libopenblas (USE64BITINT DYNAMIC_ARCH NO_AFFINITY Nehalem)
  LAPACK: libopenblas64_
  LIBM: libopenlibm
  LLVM: libLLVM-3.3
INFO: Computing test dependencies for ShapeModels...
INFO: No packages to install, update or remove
INFO: Testing ShapeModels
Running runtests.jl ...
INFO: Recompiling stale cache file /home/vagrant/.julia/lib/v0.4/HDF5.ji for module HDF5.
INFO: Recompiling stale cache file /home/vagrant/.julia/lib/v0.4/PyCall.ji for module PyCall.
ERROR: LoadError: LoadError: LoadError: InitError: Failed to pyimport("matplotlib"): PyPlot will not work until you have a functioning matplotlib module.

For automated Matplotlib installation, try configuring PyCall to use the Conda Python distribution within Julia.  Relaunch Julia and run:
      ENV["PYTHON"]=""
      Pkg.build("PyCall")
      using PyPlot

pyimport exception was: PyError (:PyImport_ImportModule) <type 'exceptions.ImportError'>
ImportError('No module named matplotlib',)

 in __init__ at /home/vagrant/.julia/v0.4/PyPlot/src/PyPlot.jl:229
 in _require_from_serialized at loading.jl:84
 in require at ./loading.jl:251
 in include at ./boot.jl:261
 in include_from_node1 at ./loading.jl:304
 in include at ./boot.jl:261
 in include_from_node1 at ./loading.jl:304
 in require at ./loading.jl:243
 in include at ./boot.jl:261
 in include_from_node1 at ./loading.jl:304
 in process_options at ./client.jl:280
 in _start at ./client.jl:378
during initialization of module PyPlot
while loading /home/vagrant/.julia/v0.4/ShapeModels/src/plotfunctions.jl, in expression starting on line 3
while loading /home/vagrant/.julia/v0.4/ShapeModels/src/ShapeModels.jl, in expression starting on line 35
while loading /home/vagrant/.julia/v0.4/ShapeModels/test/runtests.jl, in expression starting on line 2
=============================[ ERROR: ShapeModels ]=============================

failed process: Process(`/home/vagrant/julia/bin/julia --check-bounds=yes --code-coverage=none --color=no /home/vagrant/.julia/v0.4/ShapeModels/test/runtests.jl`, ProcessExited(1)) [1]

================================================================================
INFO: No packages to install, update or remove
ERROR: ShapeModels had test errors
 in error at ./error.jl:21
 in test at pkg/entry.jl:803
 in anonymous at pkg/dir.jl:31
 in cd at file.jl:22
 in cd at pkg/dir.jl:31
 in test at pkg.jl:71
 in process_options at ./client.jl:257
 in _start at ./client.jl:378

>>> End of log
